<robot  name="scara_v2_without_gripper">



  <link name="baseBox">
    <inertial>
        <origin
          xyz="0 0 0"
          rpy="0 0 0" />
        <mass
          value="1" />
        <inertia
          ixx="1"
          ixy="0"
          ixz="0"
          iyy="1"
          iyz="0"
          izz="1" />
    </inertial>
    <visual>
        <origin
          xyz="0 0 0"
          rpy="0 0 0" />
        <geometry>
          <mesh
            filename="package://scara_v2_without_gripper/meshes/baseBox.STL" />
        </geometry>
        <material
          name="">
          <color
            rgba="0.792156862745098 0.819607843137255 0.933333333333333 1" />
        </material>
    </visual>
    <collision>
        <origin
          xyz="0 0 0"
          rpy="0 0 0" />
        <geometry>
          <mesh
            filename="package://scara_v2_without_gripper/meshes/baseBox.STL" />
        </geometry>
    </collision>
  </link>

  <link
    name="ScaraBase">
    <inertial>
        <origin
          xyz="0 0 0"
          rpy="0 0 0" />
        <mass
          value="1" />
        <inertia
          ixx="1"
          ixy="0"
          ixz="0"
          iyy="1"
          iyz="0"
          izz="1" />
    </inertial>
    <visual>
        <origin
          xyz="0 0 0"
          rpy="0 0 0" />
        <geometry>
          <mesh
            filename="package://scara_v2_without_gripper/meshes/ScaraBase.STL" />
        </geometry>
        <material
          name="">
          <color
            rgba="0.792156862745098 0.819607843137255 0.933333333333333 1" />
        </material>
    </visual>
    <collision>
        <origin
          xyz="0 0 0"
          rpy="0 0 0" />
        <geometry>
          <mesh
            filename="package://scara_v2_without_gripper/meshes/ScaraBase.STL" />
        </geometry>
    </collision>
  </link>
  <joint name="Joint_Base" type="fixed">
    <parent link="baseBox" />
    <child link="ScaraBase" />
    <origin
      xyz="0.212 0.58 0.141" rpy="1.5708 0 0" />
    <axis
      xyz="1 0 0" />
  </joint>





  <link
    name="Link1">
    <inertial>
        <origin
          xyz="0 0 0"
          rpy="0 0 0" />
        <mass
          value="1" />
        <inertia
          ixx="1"
          ixy="0"
          ixz="0"
          iyy="1"
          iyz="0"
          izz="1" />
    </inertial>
    <visual>
        <origin
          xyz="0 0 0"
          rpy="0 0 0" />
        <geometry>
          <mesh
            filename="package://scara_v2_without_gripper/meshes/Link1.STL" />
        </geometry>
        <material
          name="">
          <color
            rgba="0.792156862745098 0.819607843137255 0.933333333333333 1" />
        </material>
    </visual>
    <collision>
        <origin
          xyz="0 0 0"
          rpy="0 0 0" />
        <geometry>
          <mesh
            filename="package://scara_v2_without_gripper/meshes/Link1.STL" />
        </geometry>
    </collision>
  </link>
  <joint name="Joint1" type="continuous">
    <parent link="ScaraBase" />
    <child link="Link1" />
    <origin xyz="0 0.051 0" rpy="0 0 0" />
    <axis xyz="1 0 0" />
  </joint>




  <link name="Link2">
    <inertial>
        <origin
          xyz="0 0 0"
          rpy="0 0 0" />
        <mass
          value="1" />
        <inertia
          ixx="1"
          ixy="0"
          ixz="0"
          iyy="1"
          iyz="0"
          izz="1" />
    </inertial>
    <visual>
        <origin
          xyz="0 0 0"
          rpy="0 0 0" />
        <geometry>
          <mesh
            filename="package://scara_v2_without_gripper/meshes/Link2.STL" />
        </geometry>
        <material
          name="">
          <color
            rgba="0.792156862745098 0.819607843137255 0.933333333333333 1" />
        </material>
    </visual>
    <collision>
        <origin
          xyz="0 0 0"
          rpy="0 0 0" />
        <geometry>
          <mesh
            filename="package://scara_v2_without_gripper/meshes/Link2.STL" />
        </geometry>
    </collision>
  </link>
  <joint name="Joint2" type="continuous">
    <parent link="Link1" />
    <child link="Link2" />
    <origin xyz="0.24972 -0.081 0" rpy="3.14 -1.5708 0" />
    <axis xyz="-1 0 0" />
  </joint>
</robot>